Workbook

Sheet Nhân sự
B1: Name | C1: Job | D1: Role
A2: 1 | B2: ThanLV | C2: Project Manager | D2: PM
A3: 2 | B3: HieuND97 | C3: Project Manager | D3: PM
A4: 3 | B4: NhutNM5 | C4: Project Manager | D4: PM
A5: 4 | B5: TuyenNH1 | C5: CC | D5: SA
A6: 5 | B6: HienDT25 | C6: PMO | D6: PMO
A7: 6 | B7: ThongNH7 | C7: Solution Architect | D7: SA
A8: 7 | B8: VuCH2 | C8: Solution Architect | D8: SA
A9: 8 | B9: BaoNQ12 | C9: Solution Architect | D9: SA
A10: 9 | B10: AnhHY | C10: Application Developer | D10: BE
A11: 10 | B11: TamVM7 | C11: Application Developer | D11: FE
A12: 11 | B12: AnPD3 | C12: Application Developer | D12: BE
A13: 12 | B13: ToaiND2 | C13: Application Developer | D13: BE
... A50: 49 | B50: MinhNN73 | C50: Application Developer | D50: FE

Sheet Bảng đã đổi tên
A1: employee_id | B1: full_name | C1: account | D1: contract_type | E1: hire_date | F1: job_title | G1: toeic_score | H1: certificates | I1: department | J1: location | K1: parent_department | L1: child_department | M1: main_skill | N1: seniority(main) | O1: current_skiill | P1: seniority(current)
A2: 1 | B2: An NL | C2: user001 | D2: OFF | E2: 44958 | F2: Senior Project Manager | G2: 955 | H2: EnglishScore;Project Management Professional (PMP) | I2: FHM CMS | J2: HCM | K2: FHM | L2: FHM CMS | M2: Project Management | O2: Project Management | P2: Middle
A3: 2 | B3: Binh TT | C3: user002 | D3: OFF | E3: 46082 | F3: Project Manager | I3: FHM CMS | J3: HCM | K3: FHM | L3: FHM CMS | O3: Project Management | P3: Middle
A4: 3 | B4: Cuong HP | C4: user003 | D4: OFF | E4: 44667 | F4: Associate Project Manager | G4: 910 | H4: PROFESSIONAL SCRUM MASTER™ I;EnglishScore;PROFESSIONAL SCRUM MASTER™ II;Oracle Cloud Infrastructure 2023 Certified Foundations Associate;Oracle Cloud Data Management 2023 Certified Foundations Associate;Oracle Cloud Infrastructure 2023 AI Certified Foundations Associate;Core Designer Certificate;Advanced Designer Certificate;Oracle Cloud Infrastructure for Sunbird Ed Specialty;Aptis General - Listening Reading Speaking Writing - Level B2 | I4: FHM CMS | J4: HCM | K4: FHM | L4: FHM CMS | M4: .NET Framework | N4: Junior | O4: Project Management | P4: Junior
A5: 4 | B5: Dung QA | C5: user004 | D5: OFF | E5: 43062 | F5: Project Manager | G5: 620 | H5: C++ Standard Template Library;EnglishScore;FSOFT Foreign Language Proficiency Test - TOEIC Test;PROFESSIONAL SCRUM MASTER™ I;TOEIC (Internal);PMI Agile Certified Practitioner (PMI-ACP)® | I5: FHM CMS | J5: HCM | K5: FHM | L5: FHM CMS | M5: Project Management | O5: Project Management | P5: Junior
A6: 5 | B6: Giang MK | C6: user005 | D6: OFF | E6: 45427 | F6: Senior Software Engineer | G6: 720 | H6: EnglishScore;Azure Fundamentals | I6: FHM CMS | J6: HCM | K6: FHM | L6: FHM CMS | M6: .NET Framework | O6: .NET Framework | P6: Middle
A7: 6 | B7: Hai PL | C7: user006 | D7: OFF | E7: 45870 | F7: Solution Architect | G7: 740 | H7: Google Cloud Certified Professional Cloud Developer;Google Cloud Certified - Associate Cloud Engineer;Microsoft Certified: Azure Fundamentals;Microsoft Certified: Azure Developer Associate;Microsoft Certified: Azure Data Engineer Associate;Microsoft Certified: Azure Solutions Architect Expert;Microsoft Certified: DevOps Engineer Expert;Cloud Architect using Microsoft Azure;EnglishScore;FSOFT Foreign Language Proficiency Test - TOEIC Test;GitHub Copilot;Agile Scrum Foundation;Secure Coding | I7: FHM CMS | J7: HCM | K7: FHM | L7: FHM CMS | M7: .NET Framework | O7: Azure Cloud | P7: Middle
A8: 7 | B8: Hieu DN | C8: user007 | D8: OFF | E8: 43983 | F8: Solution Architect | G8: 755 | H8: Google Cloud Certified Professional Cloud Developer;Core Designer Certificate;Advanced Designer Certificate;Microsoft Certified: Azure Data Engineer Associate;Microsoft Certified: Azure Database Administrator Associate;Microsoft Certified: Azure IoT Developer Specialty;Microsoft Certified: Azure Solutions Architect Expert;Microsoft Certified: DevOps Engineer Expert;Google Cloud Certified - Associate Cloud Engineer;Microsoft Certified: Azure Fundamentals;Microsoft Certified: Azure Developer Associate;FSOFT Foreign Language Proficiency Test - TOEIC Test;EnglishScore;Cloud Architect using Microsoft Azure | I8: FHM CMS | J8: HCM | K8: FHM | L8: FHM CMS | M8: .NET Framework | N8: Middle | O8: Azure Cloud | P8: Senior
A9: 8 | B9: Hung LH | C9: user008 | D9: OFF | E9: 43366 | F9: Associate Solution Architect | G9: 735 | H9: Microsoft Certified: Azure Solutions Architect Expert;Developing ASP.NET MVC Web Applications;Microsoft Certified: Azure Developer Associate;PROFESSIONAL SCRUM MASTER™ I;Microsoft Certified Solutions Associate: Web Applications;Cloud Native Application Architecture;Th?c s? K? thu?t Ph?n m?m (AI MSE);Google Cloud Certified: Cloud Digital Leader;Agile Development;Data Mining Foundations and Practice;Microsoft Certified: Azure DevOps Engineer Expert;Core Designer Certificate;Advanced Designer Certificate;Microsoft Specialist: Programming in C#;Microsoft Certified: Azure Fundamentals;EnglishScore;Microsoft Certified: Azure Architect Technologies;AWS Cloud Architect;FSOFT Foreign Language Proficiency Test - TOEIC Test;Associate Traditional Web Developer O11 | I9: FHM CMS | J9: HCM | K9: FHM | L9: FHM CMS | M9: Azure Cloud | O9: Azure Cloud | P9: Senior
A10: 9 | B10: Khanh BT | C10: user009 | D10: OFF | E10: 44028 | F10: Senior Software Engineer | G10: 955 | H10: Advanced Designer Certificate;Core Designer Certificate;EnglishScore;FSOFT Foreign Language Proficiency Test - TOEIC Test;GitHub Copilot;Google Cloud Certified - Associate Cloud Engineer;AWS Certified Developer - Associate;Microsoft Certified: Azure AI Engineer Associate;PROFESSIONAL SCRUM MASTER™ I;PROFESSIONAL SCRUM MASTER™ II;Enrich skills to succeed - Go Platform;AWS Certified Solutions Architect - Associate;Microsoft Certified: Azure AI Fundamentals;Microsoft Certified: Azure Data Fundamentals | I10: FHM CMS | J10: HCM | K10: FHM | L10: FHM CMS | M10: Java Framework | N10: Middle | O10: Java Framework | P10: Middle
A11: 10 | B11: Lam AK | C11: user010 | D11: OFF | E11: 45084 | F11: Senior Software Engineer | G11: 550 | H11: EnglishScore | I11: FHM CMS | J11: HCM | K11: FHM | L11: FHM CMS | M11: ReactJS Framework | N11: Senior | O11: ReactJS Framework | P11: Senior
A12: 11 | B12: Linh NL | C12: user011 | D12: OFF | E12: 46007 | F12: Senior Software Engineer | I12: FHM CMS | J12: HCM | K12: FHM | L12: FHM CMS | M12: .NET Framework | N12: Middle | O12: Java Framework | P12: Junior
A13: 12 | B13: Long TT | C13: user012 | D13: OFF | E13: 46026 | F13: Application Developer | H13: EnglishScore;Developer Certificate;GitHub Copilot;Microsoft Certified: Azure Fundamentals;Java Programming;Agile Scrum Foundation | I13: F1 JDC | J13: HCM | K13: F1 | L13: F1 JDC | M13: Java Framework | N13: Junior | O13: Java Framework | P13: Junior
A14: 13 | B14: Minh HP | C14: user013 | D14: OFF | E14: 45084 | F14: Senior Software Engineer | G14: 665 | H14: Cloud Developer;EnglishScore;Product Manager | I14: FHM CMS | J14: HCM | K14: FHM | L14: FHM CMS | M14: ReactJS Framework | N14: Middle | O14: Java Framework | P14: Middle
A15: 14 | B15: Nam QA | C15: user014 | D15: OFF | E15: 44005 | F15: Senior Business Analyst | G15: 710 | H15: EnglishScore;Japanese Language Proficiency Test N2;FSOFT Foreign Language Proficiency Test - TOEIC Test;Introduction to Data Science in Python;FSOFT Customer Interview Training;Interview Skill for Interviewer | I15: FHM CMS | J15: HCM | K15: FHM | L15: FHM CMS | M15: BA | N15: Senior | O15: BA | P15: Junior
A16: 15 | B16: Ngoc MK | C16: user015 | D16: OFF | E16: 46023 | F16: Associate Business Analyst | H16: Japanese Language Proficiency Test N3 | I16: FHM CMS | J16: HCM | K16: FHM | L16: FHM CMS | O16: BA | P16: Junior
A17: 16 | B17: Nhat PL | C17: user016 | D17: OFF | E17: 45283 | F17: Business Analyst | G17: 755 | H17: EnglishScore;Business Analytics;Developer Certificate;Generative AI Practitioner Certificate;ML Practitioner Certificate;AI in Office;Core Designer Certificate;Advanced Designer Certificate | I17: FHM CMS | J17: HCM | K17: FHM | L17: FHM CMS | M17: BA | N17: Junior | O17: BA | P17: Junior
A18: 17 | B18: Phong DN | C18: user017 | D18: OFF | E18: 45854 | F18: Business Analyst | H18: Japanese Language Proficiency Test N2 | I18: FHM CMS | J18: HCM | K18: FHM | L18: FHM CMS | O18: BA | P18: Middle
A19: 18 | B19: Phuc LH | C19: user018 | D19: OFF | E19: 45283 | F19: Business Analyst | H19: Japanese Language Proficiency Test N2;Japanese Language Proficiency Test N3;TOEIC Listening & Reading;Professional Scrum Product Owner I;Core Designer Certificate;Business Intelligence Analytics;Programming for Data Science with Python;Introduction to Python;Microsoft Certified: Azure Fundamentals;Professional Scrum Product Owner II;Certification of Capability in Business Analysis (CCBA);Introduction to Version Control | I19: FHM CMS | J19: HCM | K19: FHM | L19: FHM CMS | M19: BA | N19: Junior | O19: BA | P19: Junior
A20: 19 | B20: Quan BT | C20: user019 | D20: OFF | E20: 45283 | F20: Business Analyst | H20: SQL;Japanese Language Proficiency Test N2 | I20: FHM CMS | J20: HCM | K20: FHM | L20: FHM CMS | M20: BA | N20: Junior | O20: BA | P20: Junior
A21: 20 | B21: Thao AK | C21: user020 | D21: OFF | E21: 46014 | F21: Senior Software Engineer | I21: FHM CMS | J21: HCM | K21: FHM | L21: FHM CMS | O21: Java Framework | P21: Junior
A22: 21 | B22: Trang NL | C22: user021 | D22: OFF | E22: 46149 | F22: Senior Software Engineer | I22: FHM CMS | J22: HCM | K22: FHM | L22: FHM CMS | O22: ReactJS Framework | P22: Senior
A23: 22 | B23: Truc TT | C23: user022 | D23: OFF | E23: 45885 | F23: Senior Software Engineer | G23: 690 | H23: Microsoft Certified: Azure Data Fundamentals;PROFESSIONAL SCRUM MASTER™ I | I23: FHM CMS | J23: HCM | K23: FHM | L23: FHM CMS | M23: .NET Framework | O23: .NET Framework | P23: Middle
A24: 23 | B24: Tuan HP | C24: user023 | D24: OFF | E24: 46168 | F24: Application Developer | G24: 710 | H24: EnglishScore;Developer Certificate;GitHub Copilot;Microsoft Certified: Azure Fundamentals;Java Programming;SQL | I24: F1 JDC | J24: HCM | K24: F1 | L24: F1 JDC | M24: Java Framework | N24: Junior | O24: Java Framework | P24: Junior
A25: 24 | B25: Van QA | C25: user024 | D25: OFF | E25: 40929 | F25: Senior Business Analyst | G25: 595 | H25: FSOFT Foreign Language Proficiency Test - TOEIC Test;ISTQB Certified Tester - Foundation Level;EnglishScore | I25: FHM CMS | J25: HCM | K25: FHM | L25: FHM CMS | M25: BA | N25: Senior | O25: DevOps & CI/CD Engineering | P25: Junior
A26: 25 | B26: Vy MK | C26: user025 | D26: OFF | E26: 43182 | F26: Senior Software Engineer | G26: 575 | H26: Effective Problem-Solving and Decision-Making;Developing Web Apps (OutSystems 11);EnglishScore;FSOFT Foreign Language Proficiency Test - TOEIC Test | I26: FHM CMS | J26: HCM | K26: FHM | L26: FHM CMS | M26: .NET Framework | N26: Senior | O26: DevOps & CI/CD Engineering | P26: Junior
A27: 26 | B27: An PL | C27: user026 | D27: OFF | E27: 46174 | F27: Application Developer | G27: 880 | H27: EnglishScore;Developer Certificate;GitHub Copilot;Microsoft Certified: Azure Fundamentals;Agile Scrum Foundation | I27: F1 JDC | J27: HCM | K27: F1 | L27: F1 JDC | M27: Java Framework | N27: Junior | O27: Java Framework | P27: Junior
A28: 27 | B28: Binh DN | C28: user027 | D28: OFF | E28: 46174 | F28: Application Developer | G28: 850 | H28: Cloud Developer;EnglishScore;Product Manager;GitHub Copilot;React Developer;Microsoft Certified: Azure Fundamentals;Agile Scrum Foundation | I28: F1 JDC | J28: HCM | K28: F1 | L28: F1 JDC | M28: ReactJS Framework | N28: Middle | O28: ReactJS Framework | P28: Middle
A29: 28 | B29: Cuong LH | C29: user028 | D29: OFF | E29: 46218 | F29: Application Developer | I29: F1 JDC | J29: HCM | K29: F1 | L29: F1 JDC | M29: Java Framework | N29: Junior | O29: Java Framework | P29: Junior
A30: 29 | B30: Dung BT | C30: user029 | D30: OFF | E30: 45923 | F30: Principal Test Analyst | I30: FHM CMS | J30: HCM | K30: FHM | L30: FHM CMS | O30: Manual Test | P30: Senior
A31: 30 | B31: Giang AK | C31: user030 | D31: OFF | E31: 46168 | F31: Manual Test | I31: FHM CMS | J31: HCM | K31: FHM | L31: FHM CMS | O31: Manual Test | P31: Junior
A32: 31 | B32: Hai NL | C32: user031 | D32: OFF | E32: 45398 | F32: Senior Software Tester | G32: 710 | H32: EnglishScore;ISTQB Certified Tester Advanced Level - Test Analyst | I32: FHM CMS | J32: HCM | K32: FHM | L32: FHM CMS | O32: Manual Test | P32: Middle
A33: 32 | B33: Hieu TT | C33: user032 | D33: OFF | E33: 45937 | F33: Senior Software Tester | I33: FHM CMS | J33: HCM | K33: FHM | L33: FHM CMS | O33: Manual Test | P33: Middle
A34: 33 | B34: Hung HP | C34: user033 | D34: OFF | E34: 43206 | F34: Senior Software Engineer | G34: 620 | H34: EnglishScore;PROFESSIONAL SCRUM MASTER™ I;Developing ASP.NET MVC Web Applications;Microsoft Specialist: Programming in C#;FSOFT Foreign Language Proficiency Test - TOEIC Test;Microsoft Certified: Azure Fundamentals;Microsoft Certified: Azure DevOps Engineer Expert;Microsoft Certified: DevOps Engineer Expert;Microsoft Certified: Azure Administrator Associate;TOEIC (Internal);TOEIC Listening & Reading;Microsoft Certified: Azure Solutions Architect Expert;Microsoft Certified: Identity and Access Administrator Associate;Microsoft Certified: Security, Compliance, and Identity Fundamentals;Microsoft Certified: Azure Data Engineer Associate;Microsoft Certified: Azure Data Fundamentals;Microsoft Certified: Azure Network Engineer Associate;Microsoft Certified: Azure Developer Associate | I34: FHM CMS | J34: HCM | K34: FHM | L34: FHM CMS | M34: .NET Framework | N34: Middle | O34: Azure Cloud | P34: Senior
A35: 34 | B35: Khanh QA | C35: user034 | D35: OFF | E35: 46149 | F35: Associate Business Analyst | H35: Japanese Language Proficiency Test N3 | I35: FHM JFL | J35: HCM | K35: FHM | L35: FHM JFL | O35: BA | P35: Junior
A36: 35 | B36: Lam MK | C36: user035 | D36: OFF | E36: 46244 | F36: Manual Test | H36: ISTQB Foundation;EnglishScore;Automation Testing;API Testing | I36: IVS | J36: HCM | K36: IVS | L36: IVS | O36: Manual Test | P36: Middle
A37: 36 | B37: Linh PL | C37: user036 | D37: OFF | E37: 46237 | F37: Business Analyst | H37: EnglishScore;Business Analytics;Agile Scrum Foundation;Japanese Language Proficiency Test N3;Generative AI Practitioner Certificate | I37: FHM JFL | J37: HCM | K37: FHM | L37: FHM JFL | M37: BA | O37: BA | P37: Middle
A38: 37 | B38: Long DN | C38: user037 | D38: OFF | E38: 46237 | F38: Business Analyst | I38: FHM JFL | J38: HCM | K38: FHM | L38: FHM JFL
A39: 38 | B39: Minh LH | C39: user038 | D39: OFF | E39: 46237 | F39: Application Developer | H39: EnglishScore;Developer Certificate;GitHub Copilot;Microsoft Certified: Azure Fundamentals | I39: FHM CMS | J39: HCM | K39: FHM | L39: FHM CMS
A40: 39 | B40: Nam BT | C40: user039 | E40: 46029 | F40: Intern - DEV | I40: FHM CMS | J40: HCM | K40: FHM | L40: FHM CMS | O40: Java Framework | P40: Intern
...

Sheet Bảng nhân sự CMS
A1: No | B1: Full Name | C1: Account | D1: Contract Type | E1: Hire Date | F1: Job Title | G1: Toeic Score | H1: Certificates | I1: Department | J1: Location | K1: Parent Department | L1: Child Department | M1: Main Skill | N1: Seniority(Main) | O1: Current Skill | P1: Seniority(Current) | Q1: Job Rank | R1: Customer Co | S1: Customer code | T1: Project Dept | U1: Project co | V1: Project Co2 | W1: Project Code3 | X1: Project code 2 | Y1: Project Type | Z1: Role
A2: 1 | B2: Chu Chiêu Dủ An | C2: user001 | D2: OFF | E2: 45398 | F2: Senior Software Engineer | G2: 895 | H2: EnglishScore;Developer Certificate;Advanced Designer Certificate;ML Practitioner Certificate;MLOps Practitioner Certificate;Core Designer Certificate;GitHub Copilot;Data Engineering with Microsoft Azure;TOEIC Listening & Reading | I2: FHM CMS | J2: HCM | K2: FHM | L2: FHM CMS | M2: Java Framework | N2: Middle | O2: Java Framework | P2: Senior | Q2: DEVE03 | R2: FR | S2: =VLOOKUP(R2,Customer_Mapping!A:B,2,FALSE) -> Customer_001 | T2: FSO.HCM.FHM.CMS | U2: FRDLO | V2: FMCS3 | W2: =IF(U2="","",IFERROR(_xlfn.XLOOKUP(U2,Mapping!$A:$A,Mapping!$B:$B),"")) -> Project_001 | X2: =IF(V2="","",IFERROR(_xlfn.XLOOKUP(V2,Mapping!$A:$A,Mapping!$B:$B),"")) -> Project_017 | Y2: External | Z2: Java Framework
A3: 2 | B3: Bùi Tuấn Anh | C3: user002 | D3: OFF | E3: 44896 | F3: Software Engineer | G3: 690 | H3: Java Web Developer;EnglishScore | I3: FHM CMS | J3: HCM | K3: FHM | L3: FHM CMS | M3: Java Framework | N3: Junior | O3: IT Service | P3: Junior | Q3: DEVE02 | R3: FR | S3: =VLOOKUP(R3,Customer_Mapping!A:B,2,FALSE) -> Customer_001 | T3: FSO.HCM.FHM.CMS | U3: Portal_EU01 | V3: FRDLO | W3: =IF(U3="","",IFERROR(_xlfn.XLOOKUP(U3,Mapping!$A:$A,Mapping!$B:$B),"")) -> Project_002 | X3: =IF(V3="","",IFERROR(_xlfn.XLOOKUP(V3,Mapping!$A:$A,Mapping!$B:$B),"")) -> Project_001 | Y3: External | Z3: Java Framework
A4: 3 | B4: Huỳnh Ngọc Minh Anh | C4: user003 | D4: OFF | E4: 44902 | F4: Business Analyst | G4: 945 | H4: EnglishScore;PROFESSIONAL SCRUM MASTER™ I | I4: FHM CMS | J4: HCM | K4: FHM | L4: FHM CMS | M4: BA | N4: Junior | O4: BA | P4: Middle | Q4: BANE02 | R4: Casio-Europe | S4: =VLOOKUP(R4,Customer_Mapping!A:B,2,FALSE) -> Customer_002 | T4: FSO.HCM.FHM.CMS | U4: JOCAR_Replace | V4: Portal_EU01 | W4: =IF(U4="","",IFERROR(_xlfn.XLOOKUP(U4,Mapping!$A:$A,Mapping!$B:$B),"")) -> Project_003 | X4: =IF(V4="","",IFERROR(_xlfn.XLOOKUP(V4,Mapping!$A:$A,Mapping!$B:$B),"")) -> Project_002 | Y4: External | Z4: BA
A5: 4 | B5: Hoàng Yến Anh | C5: user004 | D5: OFF | E5: 44028 | F5: Senior Software Engineer | G5: 955 | H5: Advanced Designer Certificate;Core Designer Certificate;EnglishScore;FSOFT Foreign Language Proficiency Test - TOEIC Test;GitHub Copilot;Google Cloud Certified - Associate Cloud Engineer;AWS Certified Developer - Associate;Microsoft Certified: Azure AI Engineer Associate;PROFESSIONAL SCRUM MASTER™ I;PROFESSIONAL SCRUM MASTER™ II;Enrich skills to succeed - Go Platform;AWS Certified Solutions Architect - Associate;Microsoft Certified: Azure AI Fundamentals;Microsoft Certified: Azure Data Fundamentals | I5: FHM CMS | J5: HCM | K5: FHM | L5: FHM CMS | M5: Java Framework | N5: Middle | O5: Java Framework | P5: Middle | Q5: DEVE03 | R5: JJCM | S5: =VLOOKUP(R5,Customer_Mapping!A:B,2,FALSE) -> Customer_003 | T5: FSO.HCM.FHM.CMS | U5: FVD2025 | V5: JOCAR_Replace | W5: =IF(U5="","",IFERROR(_xlfn.XLOOKUP(U5,Mapping!$A:$A,Mapping!$B:$B),"")) -> Project_004 | X5: =IF(V5="","",IFERROR(_xlfn.XLOOKUP(V5,Mapping!$A:$A,Mapping!$B:$B),"")) -> Project_003 | Y5: External | Z5: Java Framework
A6: 5 | B6: Nguyễn Hà Kim Anh | C6: user005 | D6: OFF | E6: 46082 | F6: Associate Project Manager | H6: IELTS 6.5 | I6: FHM CMS | J6: HCM | K6: FHM | L6: FHM CMS | M6: Project Management | N6: Junior | O6: Project Management | P6: Junior | Q6: SPMA01 | R6: FR | S6: =VLOOKUP(R6,Customer_Mapping!A:B,2,FALSE) -> Customer_001 | T6: FSO.HCM.FHM.CMS | U6: SBR_Buhin26 | V6: FVD2025 | W6: =IF(U6="","",IFERROR(_xlfn.XLOOKUP(U6,Mapping!$A:$A,Mapping!$B:$B),"")) -> Project_005 | X6: =IF(V6="","",IFERROR(_xlfn.XLOOKUP(V6,Mapping!$A:$A,Mapping!$B:$B),"")) -> Project_004 | Y6: External | Z6: Project Management
A7: 6 | B7: Nông Minh Anh | C7: user006 | D7: OFF | E7: 45673 | F7: Software Engineer | H7: TOEIC Listening & Reading;Japanese Language Proficiency Test N3;GitHub Copilot | I7: FHM CMS | J7: HCM | K7: FHM | L7: FHM CMS | M7: Java Framework | N7: Junior | O7: Java Framework | P7: Middle | Q7: DEVE02 | R7: SBR | S7: =VLOOKUP(R7,Customer_Mapping!A:B,2,FALSE) -> Customer_004 | T7: FSO.HCM.FHM.CMS | U7: SDX_Y3 | V7: SBR_Buhin26 | W7: =IF(U7="","",IFERROR(_xlfn.XLOOKUP(U7,Mapping!$A:$A,Mapping!$B:$B),"")) -> Project_006 | X7: =IF(V7="","",IFERROR(_xlfn.XLOOKUP(V7,Mapping!$A:$A,Mapping!$B:$B),"")) -> Project_005 | Y7: External | Z7: Java Framework
A8: 7 | B8: Phạm Lê Thế Anh | C8: user007 | D8: OFF | E8: 44667 | F8: Software Engineer | G8: 640 | H8: EnglishScore;Microsoft Certified: Azure Developer Associate;Software Engineer Intern;Advanced Designer Certificate;IELTS 5.5;Microsoft Certified: Azure Fundamentals | I8: FHM CMS | J8: HCM | K8: FHM | L8: FHM CMS | M8: AWS Cloud | O8: DevOps & CI/CD Engineering | P8: Middle | Q8: DEVE02 | R8: Sodexo | S8: =VLOOKUP(R8,Customer_Mapping!A:B,2,FALSE) -> Customer_005 | T8: FSO.HCM.FHM.CMS | U8: CDX_MS | V8: SDX_Y3 | W8: =IF(U8="","",IFERROR(_xlfn.XLOOKUP(U8,Mapping!$A:$A,Mapping!$B:$B),"")) -> Project_007 | X8: =IF(V8="","",IFERROR(_xlfn.XLOOKUP(V8,Mapping!$A:$A,Mapping!$B:$B),"")) -> Project_006 | Y8: External | Z8: AWS Cloud
A9: 8 | B9: Trần Quỳnh Anh | C9: user008 | D9: OFF | E9: 46060 | F9: Associate Project Manager | I9: FHM JFL | J9: HCM | K9: FHM | L9: FHM JFL | M9: Project Management | N9: Junior | O9: Project Management | P9: Junior | Q9: SPMA01 | R9: SonyGS | S9: =VLOOKUP(R9,Customer_Mapping!A:B,2,FALSE) -> Customer_006 | T9: FSO.HCM.FHM.CMS | U9: SF_Link_2026 | V9: CDX_MS | W9: =IF(U9="","",IFERROR(_xlfn.XLOOKUP(U9,Mapping!$A:$A,Mapping!$B:$B),"")) -> Project_008 | X9: =IF(V9="","",IFERROR(_xlfn.XLOOKUP(V9,Mapping!$A:$A,Mapping!$B:$B),"")) -> Project_007 | Y9: External | Z9: Project Management
A10: 9 | B10: Nguyễn Thị Duy An | C10: user009 | D10: OFF | E10: 45200 | F10: Senior Software Tester | G10: 550 | H10: EnglishScore;Model Context Protocol: Advanced Topics;Introduction to Agent Skills;Cluade Code in Action;Introduction to Model Context Protocol;Claude Code 101;Claude with the Anthropic API;Introduction to Claude Cowork;Introduction to subagents;ISTQB Certified Tester - Foundation Level;Agile Software Developer;Oracle Cloud Infrastructure 2023 Certified Foundations Associate;Oracle Cloud Infrastructure for Sunbird Ed Specialty | I10: FHM CMS | J10: HCM | K10: FHM | L10: FHM CMS | M10: Manual Test | N10: Senior | O10: Manual Test | P10: Junior | Q10: TEST04 | R10: SBR | S10: =VLOOKUP(R10,Customer_Mapping!A:B,2,FALSE) -> Customer_004 | T10: FSO.HCM.FHM.CMS | U10: JOCAR_Replace | V10: SF_Link_2026 | W10: =IF(U10="","",IFERROR(_xlfn.XLOOKUP(U10,Mapping!$A:$A,Mapping!$B:$B),"")) -> Project_003 | X10: =IF(V10="","",IFERROR(_xlfn.XLOOKUP(V10,Mapping!$A:$A,Mapping!$B:$B),"")) -> Project_008 | Y10: External | Z10: Manual Test
A11: 10 | B11: Phạm Duy An | C11: user010 | D11: OFF | E11: 46007 | F11: Senior Software Engineer | I11: FHM CMS | J11: HCM | K11: FHM | L11: FHM CMS | M11: .NET Framework | N11: Middle | O11: Java Framework | P11: Junior | Q11: DEVE03 | R11: JJCM | S11: =VLOOKUP(R11,Customer_Mapping!A:B,2,FALSE) -> Customer_003 | T11: FSO.HCM.FHM.CMS | U11: STL_AG_02 | V11: JOCAR_Replace | W11: =IF(U11="","",IFERROR(_xlfn.XLOOKUP(U11,Mapping!$A:$A,Mapping!$B:$B),"")) -> Project_009 | X11: =IF(V11="","",IFERROR(_xlfn.XLOOKUP(V11,Mapping!$A:$A,Mapping!$B:$B),"")) -> Project_003 | Y11: External | Z11: .NET Framework
A12: 11 | B12: Phan Đình Thiên Ân | C12: user011 | D12: OFF | E12: 45114 | F12: Software Engineer | G12: 895 | H12: GitHub Copilot;EnglishScore;Japanese Language Proficiency Test N5;TOEIC Listening & Reading;JUNIOR ANGULAR DEVELOPER;PROFESSIONAL SCRUM MASTER™ I;Oracle Cloud Infrastructure for Sunbird Ed Specialty;Oracle Cloud Infrastructure 2023 AI Certified Foundations Associate;Core Designer Certificate;Advanced Designer Certificate;Microsoft Certified: Azure Fundamentals;NVIDIA Getting Started with AI on Jetson Nano;Oracle Cloud Data Management 2023 Certified Foundations Associate;Oracle Cloud Infrastructure 2023 Certified Foundations Associate;Microsoft Certified: Azure AI Engineer Associate | I12: FHM CMS | J12: HCM | K12: FHM | L12: FHM CMS | M12: ReactJS Framework | O12: ReactJS Framework | P12: Junior | Q12: DEVE02 | R12: ANA | S12: =VLOOKUP(R12,Customer_Mapping!A:B,2,FALSE) -> Customer_007 | T12: FSO.HCM.FHM.CMS | U12: SIQAX3 | V12: STL_AG_02 | W12: =IF(U12="","",IFERROR(_xlfn.XLOOKUP(U12,Mapping!$A:$A,Mapping!$B:$B),"")) -> Project_010 | X12: =IF(V12="","",IFERROR(_xlfn.XLOOKUP(V12,Mapping!$A:$A,Mapping!$B:$B),"")) -> Project_009 | Y12: External | Z12: ReactJS Framework
A13: 12 | B13: Phạm Trường An | C13: user012 | D13: OFF | E13: 44400 | F13: Senior Software Engineer | G13: 690 | H13: Cloud Developer using Microsoft Azure;EnglishScore;Core Designer Certificate;Advanced Designer Certificate;Cloud Architect using Microsoft Azure;IELTS 5.0;Microsoft Certified: Azure Developer Associate;Microsoft Certified: Azure Fundamentals;Microsoft Certified: Azure Data Fundamentals | I13: FHM CMS | J13: HCM | K13: FHM | L13: FHM CMS | M13: .NET Framework | N13: Middle | O13: Azure Cloud | P13: Senior | Q13: DEVE03 | R13: SmartGroup | S13: =VLOOKUP(R13,Customer_Mapping!A:B,2,FALSE) -> Customer_008 | T13: FSO.HCM.FHM.CMS | U13: C99.CMS.AUD.IPDS 2026 | V13: SIQAX3 | W13: =IF(U13="","",IFERROR(_xlfn.XLOOKUP(U13,Mapping!$A:$A,Mapping!$B:$B),"")) -> Project_011 | X13: =IF(V13="","",IFERROR(_xlfn.XLOOKUP(V13,Mapping!$A:$A,Mapping!$B:$B),"")) -> Project_010 | Y13: External | Z13: .NET Framework
A14: 13 | B14: Trần Võ Hoàng Trọng Ân | C14: user013 | D14: OFF | E14: 45754 | F14: Software Engineer | H14: GitHub Copilot | I14: FHM CMS | J14: HCM | K14: FHM | L14: FHM CMS | M14: Java Framework | N14: Junior | O14: Java Framework | P14: Middle | Q14: DEVE02 | R14: COX-AM | S14: =VLOOKUP(R14,Customer_Mapping!A:B,2,FALSE) -> Customer_009 | T14: FSO.HCM.FHM.AKAT | U14: FVD2025 | V14: C99.CMS.AUD.IPDS 2026 | W14: =IF(U14="","",IFERROR(_xlfn.XLOOKUP(U14,Mapping!$A:$A,Mapping!$B:$B),"")) -> Project_004 | X14: =IF(V14="","",IFERROR(_xlfn.XLOOKUP(V14,Mapping!$A:$A,Mapping!$B:$B),"")) -> Project_011 | Y14: External | Z14: Java Framework
A15: 14 | B15: Võ Gia Ân | C15: user014 | D15: OFF | E15: 46060 | F15: Associate Software Engineer | H15: IELTS 6.5 | I15: FHM CMS | J15: HCM | K15: FHM | L15: FHM CMS | M15: Java Framework | N15: Junior | O15: Java Framework | P15: Junior | Q15: DEVE01 | R15: FR | S15: =VLOOKUP(R15,Customer_Mapping!A:B,2,FALSE) -> Customer_001 | T15: FSO.HCM.FHM.CMS | U15: C99.I5.LOG 2026 | V15: FVD2025 | W15: =IF(U15="","",IFERROR(_xlfn.XLOOKUP(U15,Mapping!$A:$A,Mapping!$B:$B),"")) -> Project_012 | X15: =IF(V15="","",IFERROR(_xlfn.XLOOKUP(V15,Mapping!$A:$A,Mapping!$B:$B),"")) -> Project_004 | Y15: External | Z15: Java Framework
A16: 15 | B16: Lương Xuân Bách | C16: user015 | D16: OFF | E16: 45419 | F16: Associate Software Engineer | G16: 895 | H16: EnglishScore | I16: FHM CMS | J16: HCM | K16: FHM | L16: FHM CMS | M16: Java Framework | N16: Junior | O16: .NET Framework | P16: Middle | Q16: DEVE01 | R16: COX-AM | S16: =VLOOKUP(R16,Customer_Mapping!A:B,2,FALSE) -> Customer_009 | T16: FSO.HCM.FHM.AKAT | U16: FRWMS2026 | V16: C99.I5.LOG 2026 | W16: =IF(U16="","",IFERROR(_xlfn.XLOOKUP(U16,Mapping!$A:$A,Mapping!$B:$B),"")) -> Project_013 | X16: =IF(V16="","",IFERROR(_xlfn.XLOOKUP(V16,Mapping!$A:$A,Mapping!$B:$B),"")) -> Project_012 | Y16: External | Z16: Java Framework
A17: 16 | B17: Phạm Công Bằng | C17: user016 | D17: OFF | E17: 45480 | F17: Senior Solution Architect | G17: 800 | H17: TOEFL ITP;EnglishScore | I17: FHM CMS | J17: HCM | K17: FHM | L17: FHM CMS | M17: Software Solution Architecture | O17: Java Framework | P17: Senior | Q17: SARE03 | R17: FR | S17: =VLOOKUP(R17,Customer_Mapping!A:B,2,FALSE) -> Customer_001 | T17: FSO.HCM.FHM.CMS | U17: NEWKONG2 | V17: FRWMS2026 | W17: =IF(U17="","",IFERROR(_xlfn.XLOOKUP(U17,Mapping!$A:$A,Mapping!$B:$B),"")) -> Project_014 | X17: =IF(V17="","",IFERROR(_xlfn.XLOOKUP(V17,Mapping!$A:$A,Mapping!$B:$B),"")) -> Project_013 | Y17: External | Z17: Software Solution Architecture
A18: 17 | B18: Đinh Thái Bảo | C18: user017 | D18: OFF | E18: 44013 | F18: Associate Project Manager | G18: 800 | H18: PROFESSIONAL SCRUM MASTER™ I;Advanced Designer Certificate;MLOps Practitioner Certificate;Core Designer Certificate;ML Practitioner Certificate;Developer Certificate;Oracle Cloud Data Management 2023 Certified Foundations Associate;SQL (Advanced);Google Analytics Certification;Oracle Cloud Infrastructure 2023 AI Certified Foundations Associate;ISTQB Certified Tester Advanced Level - Test Analyst;ISTQB Certified Tester - Foundation Level;FSOFT Foreign Language Proficiency Test - TOEIC Test;Product Manager;EnglishScore | I18: FHM CMS | J18: HCM | K18: FHM | L18: FHM CMS | M18: Manual Test | N18: Senior | O18: Manual Test | P18: Junior | Q18: SPMA01 | R18: FXSS | S18: =VLOOKUP(R18,Customer_Mapping!A:B,2,FALSE) -> Customer_010 | T18: FSO.HCM.FHM.CMS | U18: JOCAR_Replace | V18: NEWKONG2 | W18: =IF(U18="","",IFERROR(_xlfn.XLOOKUP(U18,Mapping!$A:$A,Mapping!$B:$B),"")) -> Project_003 | X18: =IF(V18="","",IFERROR(_xlfn.XLOOKUP(V18,Mapping!$A:$A,Mapping!$B:$B),"")) -> Project_014 | Y18: External | Z18: Manual Test
A19: 18 | B19: Nguyễn Quốc Bảo | C19: user018 | D19: OFF | E19: 43366 | F19: Associate Solution Architect | G19: 735 | H19: Microsoft Certified: Azure Solutions Architect Expert;Developing ASP.NET MVC Web Applications;Microsoft Certified: Azure Developer Associate;PROFESSIONAL SCRUM MASTER™ I;Microsoft Certified Solutions Associate: Web Applications;Cloud Native Application Architecture;Th?c s? K? thu?t Ph?n m?m (AI MSE);Google Cloud Certified: Cloud Digital Leader;Agile Development;Data Mining Foundations and Practice;Microsoft Certified: Azure DevOps Engineer Expert;Core Designer Certificate;Advanced Designer Certificate;Microsoft Specialist: Programming in C#;Microsoft Certified: Azure Fundamentals;EnglishScore;Microsoft Certified: Azure Architect Technologies;AWS Cloud Architect;FSOFT Foreign Language Proficiency Test - TOEIC Test;Associate Traditional Web Developer O11 | I19: FHM CMS | J19: HCM | K19: FHM | L19: FHM CMS | M19: Azure Cloud | O19: Azure Cloud | P19: Senior | Q19: SARE01 | R19: JJCM | S19: =VLOOKUP(R19,Customer_Mapping!A:B,2,FALSE) -> Customer_003 | T19: FSO.HCM.FHM.CMS | U19: SCU100 | V19: JOCAR_Replace | W19: =IF(U19="","",IFERROR(_xlfn.XLOOKUP(U19,Mapping!$A:$A,Mapping!$B:$B),"")) -> Project_015 | X19: =IF(V19="","",IFERROR(_xlfn.XLOOKUP(V19,Mapping!$A:$A,Mapping!$B:$B),"")) -> Project_003 | Y19: External | Z19: Azure Cloud
A20: 19 | B20: Phạm Hoàng Bảo | C20: user019 | D20: OFF | E20: 45154 | F20: Senior Software Engineer | G20: 690 | H20: AWS Certified Solutions Architect - Associate;Oracle Cloud Infrastructure for Sunbird Ed Specialty;Advanced Designer Certificate;Core Designer Certificate;EnglishScore | I20: FHM CMS | J20: HCM | K20: FHM | L20: FHM CMS | M20: .NET Framework | N20: Middle | O20: .NET Framework | P20: Middle | Q20: DEVE03 | R20: ISCUBE | S20: =VLOOKUP(R20,Customer_Mapping!A:B,2,FALSE) -> Customer_011 | T20: FSO.HCM.FHM.CMS | U20: C99.I5.LOG 2026 | V20: SCU100 | W20: =IF(U20="","",IFERROR(_xlfn.XLOOKUP(U20,Mapping!$A:$A,Mapping!$B:$B),"")) -> Project_012 | X20: =IF(V20="","",IFERROR(_xlfn.XLOOKUP(V20,Mapping!$A:$A,Mapping!$B:$B),"")) -> Project_015 | Y20: External | Z20: .NET Framework
A21: 20 | B21: Phạm Trần Huy Bảo | C21: user020 | D21: OFF | E21: 44850 | F21: Software Engineer | G21: 950 | H21: Vietnamese Standardized Test of English Proficiency (VSTEP) - Level 3/CEFR B1;Microsoft Certified: Azure Fundamentals;Full Stack Web Developer;Core Designer Certificate;Advanced Designer Certificate;EnglishScore;Java Fundamentals;Advanced Java Programming Techniques;Intermediate JavaScript;Front End Web Developer | I21: FHM CMS | J21: HCM | K21: FHM | L21: FHM CMS | M21: .NET Framework | N21: Junior | O21: .NET Framework | P21: Junior | Q21: DEVE02 | R21: COX-AM | S21: =VLOOKUP(R21,Customer_Mapping!A:B,2,FALSE) -> Customer_009 | T21: FSO.HCM.FHM.AKAT | U21: STL_AG_02 | V21: C99.I5.LOG 2026 | W21: =IF(U21="","",IFERROR(_xlfn.XLOOKUP(U21,Mapping!$A:$A,Mapping!$B:$B),"")) -> Project_009 | X21: =IF(V21="","",IFERROR(_xlfn.XLOOKUP(V21,Mapping!$A:$A,Mapping!$B:$B),"")) -> Project_012 | Y21: External | Z21: .NET Framework
A22: 21 | B22: Trần Gia Bảo | C22: user021 | D22: OFF | E22: 45642 | F22: Associate Data Engineer | H22: SQL (Basic) | I22: FHM CMS | J22: HCM | K22: FHM | L22: FHM CMS | M22: DE | N22: Junior | O22: DE | P22: Middle | Q22: DSEN01 | R22: ANA | S22: =VLOOKUP(R22,Customer_Mapping!A:B,2,FALSE) -> Customer_007 | T22: FSO.HCM.FHM.CMS | U22: FRWMS2026 | V22: STL_AG_02 | W22: =IF(U22="","",IFERROR(_xlfn.XLOOKUP(U22,Mapping!$A:$A,Mapping!$B:$B),"")) -> Project_013 | X22: =IF(V22="","",IFERROR(_xlfn.XLOOKUP(V22,Mapping!$A:$A,Mapping!$B:$B),"")) -> Project_009 | Y22: External | Z22: DE
A23: 22 | B23: Trần Hoài Bảo | C23: user022 | D23: OFF | E23: 44568 | F23: Senior Software Engineer | G23: 640 | H23: Cloud Architect using Microsoft Azure;EnglishScore;AWS Cloud Architect;Microsoft Certified: Azure Solutions Architect Expert;Microsoft Certified: Azure Administrator Associate;Professional Scrum Product Owner I;Cloud Developer;Cloud Developer using Microsoft Azure;NVIDIA Getting Started with AI on Jetson Nano;Oracle Cloud Data Management 2023 Certified Foundations Associate;Oracle Cloud Infrastructure 2023 Certified Foundations Associate;PROFESSIONAL SCRUM MASTER™ I;Microsoft Certified: Azure Developer Associate;Microsoft Certified: Azure Fundamentals;Microsoft Certified: Azure Data Fundamentals | I23: FHM CMS | J23: HCM | K23: FHM | L23: FHM CMS | M23: Azure Cloud | O23: Azure Cloud | P23: Middle | Q23: DEVE03 | R23: FR | S23: =VLOOKUP(R23,Customer_Mapping!A:B,2,FALSE) -> Customer_001 | T23: FSO.HCM.FHM.CMS | U23: STL_AG_02 | V23: FRWMS2026 | W23: =IF(U23="","",IFERROR(_xlfn.XLOOKUP(U23,Mapping!$A:$A,Mapping!$B:$B),"")) -> Project_009 | X23: =IF(V23="","",IFERROR(_xlfn.XLOOKUP(V23,Mapping!$A:$A,Mapping!$B:$B),"")) -> Project_013 | Y23: External | Z23: Azure Cloud
A24: 23 | B24: Trần Lê Chi Bảo | C24: user023 | D24: OFF | E24: 46113 | F24: Associate Business Analyst | H24: Japanese Language Proficiency Test N2 | I24: FHM CMS | J24: HCM | K24: FHM | L24: FHM CMS | M24: BA | N24: Junior | O24: Project Management | P24: Junior | Q24: BANE01 | R24: ANA | S24: =VLOOKUP(R24,Customer_Mapping!A:B,2,FALSE) -> Customer_007 | T24: FSO.HCM.FHM.CMS | U24: SBR_Buhin26 | V24: STL_AG_02 | W24: =IF(U24="","",IFERROR(_xlfn.XLOOKUP(U24,Mapping!$A:$A,Mapping!$B:$B),"")) -> Project_005 | X24: =IF(V24="","",IFERROR(_xlfn.XLOOKUP(V24,Mapping!$A:$A,Mapping!$B:$B),"")) -> Project_009 | Y24: External | Z24: BA
A25: 24 | B25: Văn Quốc Bảo | C25: user024 | D25: OFF | E25: 44621 | F25: Senior Software Engineer | G25: 880 | H25: EnglishScore;Generative AI Practitioner Certificate;Professional Scrum Developer I;Oracle Cloud Infrastructure for Sunbird Ed Specialty;Core Designer Certificate;Advanced Designer Certificate;NVIDIA Getting Started with AI on Jetson Nano;PROFESSIONAL SCRUM MASTER™ I | I25: FHM CMS | J25: HCM | K25: FHM | L25: FHM CMS | M25: DevOps & CI/CD Engineering | O25: DevOps & CI/CD Engineering | P25: Middle | Q25: DEVE03 | R25: SBR | S25: =VLOOKUP(R25,Customer_Mapping!A:B,2,FALSE) -> Customer_004 | T25: FSO.HCM.FHM.CMS | U25: C99.I5.WM.AA 2026 | V25: SBR_Buhin26 | W25: =IF(U25="","",IFERROR(_xlfn.XLOOKUP(U25,Mapping!$A:$A,Mapping!$B:$B),"")) -> Project_016 | X25: =IF(V25="","",IFERROR(_xlfn.XLOOKUP(V25,Mapping!$A:$A,Mapping!$B:$B),"")) -> Project_005 | Y25: External | Z25: DevOps & CI/CD Engineering
A26: 25 | B26: Lê Thái Bình | C26: user025 | D26: OFF | E26: 46014 | F26: Senior Software Engineer | H26: Microsoft Certified: Azure AI Apps and Agents Developer Associate;Microsoft Certified: Agentic AI Business Solutions Architect;Vietnamese Standardized Test of English Proficiency (VSTEP) - Level 4/CEFR B2;GitHub Copilot | I26: FHM CMS | J26: HCM | K26: FHM | L26: FHM CMS | M26: Java Framework | N26: Middle | O26: Java Framework | P26: Senior | Q26: DEVE03 | R26: COX-AM | S26: =VLOOKUP(R26,Customer_Mapping!A:B,2,FALSE) -> Customer_009 | T26: FSO.HCM.FHM.AKAT | U26: FMCS3 | V26: C99.I5.WM.AA 2026 | W26: =IF(U26="","",IFERROR(_xlfn.XLOOKUP(U26,Mapping!$A:$A,Mapping!$B:$B),"")) -> Project_017 | X26: =IF(V26="","",IFERROR(_xlfn.XLOOKUP(V26,Mapping!$A:$A,Mapping!$B:$B),"")) -> Project_016 | Y26: External | Z26: Java Framework
A27: 26 | B27: Thạch Thanh Bình | C27: user026 | D27: OFF | E27: 43974 | F27: Senior Software Engineer | G27: 800 | H27: Advanced Designer Certificate;Core Designer Certificate;Agile with Atlassian Jira;Communication in the 21st Century Workplace;Project Management: The Basics for Success;Microsoft Certified: Azure Fundamentals;FSOFT Foreign Language Proficiency Test - TOEIC Test;EnglishScore | I27: FHM CMS | J27: HCM | K27: FHM | L27: FHM CMS | M27: Java Framework | N27: Middle | O27: Java Framework | P27: Senior | Q27: DEVE03 | R27: FR | S27: =VLOOKUP(R27,Customer_Mapping!A:B,2,FALSE) -> Customer_001 | T27: FSO.HCM.FHM.CMS | U27: MetalAlpha | V27: FMCS3 | W27: =IF(U27="","",IFERROR(_xlfn.XLOOKUP(U27,Mapping!$A:$A,Mapping!$B:$B),"")) -> Project_018 | X27: =IF(V27="","",IFERROR(_xlfn.XLOOKUP(V27,Mapping!$A:$A,Mapping!$B:$B),"")) -> Project_017 | Y27: External | Z27: Java Framework
A28: 27 | B28: Y In Byă | C28: user027 | D28: OFF | E28: 45123 | F28: Senior Software Engineer | G28: 665 | H28: EnglishScore;Advanced Designer Certificate | I28: FHM CMS | J28: HCM | K28: FHM | L28: FHM CMS | M28: Java Framework | N28: Middle | O28: Java Framework | P28: Junior | Q28: DEVE03 | R28: MOC | S28: =VLOOKUP(R28,Customer_Mapping!A:B,2,FALSE) -> Customer_012 | T28: FSO.HCM.FHM.CMS | U28: J_POLARIS | V28: MetalAlpha | W28: =IF(U28="","",IFERROR(_xlfn.XLOOKUP(U28,Mapping!$A:$A,Mapping!$B:$B),"")) -> Project_019 | X28: =IF(V28="","",IFERROR(_xlfn.XLOOKUP(V28,Mapping!$A:$A,Mapping!$B:$B),"")) -> Project_018 | Y28: External | Z28: Java Framework
A29: 28 | B29: Đỗ Minh Chánh | C29: user028 | D29: OFF | E29: 45496 | F29: Associate Solution Architect | H29: Claude Certified Architect - Foundations;Japanese Language Proficiency Test N2;TOEIC Listening & Reading;AWS Certified Developer - Associate;AWS Certified Solutions Architect - Associate;Salesforce Certified Associate | I29: FHM JFL | J29: HCM | K29: FHM | L29: FHM JFL | M29: AWS Cloud | O29: AWS Cloud | P29: Middle | Q29: SARE01 | R29: JIT | S29: =VLOOKUP(R29,Customer_Mapping!A:B,2,FALSE) -> Customer_013 | T29: FSO.HCM.FHM.JPG | U29: OPNEXT88 | V29: J_POLARIS | W29: =IF(U29="","",IFERROR(_xlfn.XLOOKUP(U29,Mapping!$A:$A,Mapping!$B:$B),"")) -> Project_020 | X29: =IF(V29="","",IFERROR(_xlfn.XLOOKUP(V29,Mapping!$A:$A,Mapping!$B:$B),"")) -> Project_019 | Y29: External | Z29: AWS Cloud
A30: 29 | B30: Nguyễn Ngọc Bảo Chân | C30: user029 | D30: OFF | E30: 44005 | F30: Senior Software Tester | G30: 865 | H30: Data Analysis and Visualization with Microsoft Power BI;EnglishScore;FSOFT Foreign Language Proficiency Test - TOEIC Test;Business Intelligence Analytics;Tiếng Trung;A Life of Happiness and Fulfillment;AI for Everyone | I30: FHM CMS | J30: HCM | K30: FHM | L30: FHM CMS | M30: Manual Test | N30: Senior | O30: Manual Test | P30: Middle | Q30: TEST04 | R30: OddsPark | S30: =VLOOKUP(R30,Customer_Mapping!A:B,2,FALSE) -> Customer_014 | T30: FSO.HCM.FHM.JPG | U30: FR.SF.2025 | V30: OPNEXT88 | W30: =IF(U30="","",IFERROR(_xlfn.XLOOKUP(U30,Mapping!$A:$A,Mapping!$B:$B),"")) -> Project_021 | X30: =IF(V30="","",IFERROR(_xlfn.XLOOKUP(V30,Mapping!$A:$A,Mapping!$B:$B),"")) -> Project_020 | Y30: External | Z30: Manual Test
A31: 30 | B31: Lê Thị Xuân Chi | C31: user030 | D31: OFF | E31: 45246 | F31: Senior Software Tester | G31: 640 | H31: Oracle Cloud Infrastructure for Sunbird Ed Specialty;Advanced Designer Certificate;EnglishScore | I31: FHM CMS | J31: HCM | K31: FHM | L31: FHM CMS | M31: Manual Test | N31: Senior | O31: Low-Code & No-Code Development | P31: Middle | Q31: TEST04 | R31: FR | S31: =VLOOKUP(R31,Customer_Mapping!A:B,2,FALSE) -> Customer_001 | T31: FSO.HCM.FHM.CMS | U31: FR VDMC Operation 2026 | V31: FR.SF.2025 | W31: =IF(U31="","",IFERROR(_xlfn.XLOOKUP(U31,Mapping!$A:$A,Mapping!$B:$B),"")) -> Project_022 | X31: =IF(V31="","",IFERROR(_xlfn.XLOOKUP(V31,Mapping!$A:$A,Mapping!$B:$B),"")) -> Project_021 | Y31: External | Z31: Manual Test
A32: 31 | B32: Đặng Ngọc Chính | C32: user031 | D32: OFF | E32: 44485 | F32: Project Manager | G32: 755 | H32: PMI Agile Certified Practitioner (PMI-ACP)®;Project Management Professional (PMP);Phần cứng máy tính;Excel Skills for Business: Essentials;Developer Certificate;MLOps Practitioner Certificate;Core Designer Certificate;ML Practitioner Certificate;Advanced Designer Certificate;Google Project Management;Project Initiation: Starting a Successful Project;Project Planning: Putting It All Together;Foundations of Project Management;Project Execution: Running the Project;EnglishScore;FSOFT Foreign Language Proficiency Test - TOEIC Test | I32: FHM CMS | J32: HCM | K32: FHM | L32: FHM CMS | M32: Project Management | O32: IT Service | P32: Senior | Q32: SPMA02 | R32: FR | S32: =VLOOKUP(R32,Customer_Mapping!A:B,2,FALSE) -> Customer_001 | T32: FSO.HCM.FHM.CMS | U32: SF_Link_2026 | V32: FR VDMC Operation 2026 | W32: =IF(U32="","",IFERROR(_xlfn.XLOOKUP(U32,Mapping!$A:$A,Mapping!$B:$B),"")) -> Project_008 | X32: =IF(V32="","",IFERROR(_xlfn.XLOOKUP(V32,Mapping!$A:$A,Mapping!$B:$B),"")) -> Project_022 | Y32: External | Z32: Project Management
A33: 32 | B33: Nguyễn Nhân Chính | C33: user032 | D33: OFF | E33: 45992 | F33: Associate Software Engineer | H33: GitHub Copilot | I33: FHM CMS | J33: HCM | K33: FHM | L33: FHM CMS | M33: .NET Framework | N33: Junior | O33: Java Framework | P33: Junior | Q33: DEVE01 | R33: SBR | S33: =VLOOKUP(R33,Customer_Mapping!A:B,2,FALSE) -> Customer_004 | T33: FSO.HCM.FHM.CMS | U33: SBR_Buhin26 | V33: SF_Link_2026 | W33: =IF(U33="","",IFERROR(_xlfn.XLOOKUP(U33,Mapping!$A:$A,Mapping!$B:$B),"")) -> Project_005 | X33: =IF(V33="","",IFERROR(_xlfn.XLOOKUP(V33,Mapping!$A:$A,Mapping!$B:$B),"")) -> Project_008 | Y33: External | Z33: .NET Framework
A34: 33 | B34: Lê Thị Chung | C34: user033 | D34: OFF | E34: 44697 | F34: Senior Software Tester | G34: 575 | H34: EnglishScore;ISTQB Certified Tester Advanced Level - Test Analyst;Oracle Cloud Infrastructure for Sunbird Ed Specialty;Advanced Designer Certificate;Core Designer Certificate;Certified Tester ISTQB Foundation Level | I34: FHM CMS | J34: HCM | K34: FHM | L34: FHM CMS | M34: Manual Test | N34: Junior | O34: Manual Test | P34: Middle | Q34: TEST03 | R34: SBR | S34: =VLOOKUP(R34,Customer_Mapping!A:B,2,FALSE) -> Customer_004 | T34: FSO.HCM.FHM.CMS | U34: FRWMS2026 | V34: SBR_Buhin26 | W34: =IF(U34="","",IFERROR(_xlfn.XLOOKUP(U34,Mapping!$A:$A,Mapping!$B:$B),"")) -> Project_013 | X34: =IF(V34="","",IFERROR(_xlfn.XLOOKUP(V34,Mapping!$A:$A,Mapping!$B:$B),"")) -> Project_005 | Y34: External | Z34: Manual Test
A35: 34 | B35: Đặng Hồ Tuấn Cường | C35: user034 | D35: OFF | E35: 46180 | F35: Associate Software Engineer | I35: FHM CMS | J35: HCM | K35: FHM | L35: FHM CMS | O35: Java Framework | P35: Junior | Q35: DEVE01 | R35: FR | S35: =VLOOKUP(R35,Customer_Mapping!A:B,2,FALSE) -> Customer_001 | T35: FSO.HCM.FHM.CMS | U35: NEWKONG2 | V35: FRWMS2026 | W35: =IF(U35="","",IFERROR(_xlfn.XLOOKUP(U35,Mapping!$A:$A,Mapping!$B:$B),"")) -> Project_014 | X35: =IF(V35="","",IFERROR(_xlfn.XLOOKUP(V35,Mapping!$A:$A,Mapping!$B:$B),"")) -> Project_013 | Y35: External
A36: 35 | B36: Dương Mạnh Cường | C36: user035 | D36: OFF | E36: 41928 | F36: Software Development Head | G36: 960 | H36: Japanese Language Proficiency Test N2;EnglishScore;FSOFT Foreign Language Proficiency Test - TOEIC Test;Project Management Professional (PMP);AWS Certified Solutions Architect - Associate;Microsoft Certified Solutions Associate: Web Applications;Microsoft Specialist: Programming in HTML5 with JavaScript and CSS3;Predix Certified Developer;Self Awareness and the Effective Leader;Leadership Communication for Maximum Impact: Storytelling;Advanced Designer Certificate;Microsoft Certified Professional;Microsoft Certified Solutions Developer: Web Applications;PROFESSIONAL SCRUM MASTER™ I;Microsoft Certified: Azure Architect Technologies;Microsoft Certified: Azure Solutions Architect Expert | I36: FHM CMS | J36: HCM | K36: FHM | L36: FHM CMS | M36: Software Solution Architecture | O36: Software Solution Architecture | P36: Senior | Q36: SGMT01 | R36: FXSS | S36: =VLOOKUP(R36,Customer_Mapping!A:B,2,FALSE) -> Customer_010 | T36: FSO.HCM.FHM.CMS | U36: C99.I5.WM.AA 2026 | V36: NEWKONG2 | W36: =IF(U36="","",IFERROR(_xlfn.XLOOKUP(U36,Mapping!$A:$A,Mapping!$B:$B),"")) -> Project_016 | X36: =IF(V36="","",IFERROR(_xlfn.XLOOKUP(V36,Mapping!$A:$A,Mapping!$B:$B),"")) -> Project_014 | Y36: External | Z36: Software Solution Architecture
A37: 36 | B37: Nguyễn Kiên Cường | C37: user036 | D37: OFF | E37: 45338 | F37: Software Engineer | G37: 865 | H37: Advanced Designer Certificate;Core Designer Certificate;NVIDIA Getting Started with AI on Jetson Nano;MLOps Practitioner Certificate;TOEIC Listening & Reading;Developer Certificate;ML Practitioner Certificate;EnglishScore;AWS Certified Solutions Architect - Associate;GitHub Copilot | I37: FHM CMS | J37: HCM | K37: FHM | L37: FHM CMS | M37: NodeJs Server Implementation | N37: Junior | O37: Java Framework | P37: Middle | Q37: DEVE02 | R37: COX-AM | S37: =VLOOKUP(R37,Customer_Mapping!A:B,2,FALSE) -> Customer_009 | T37: FSO.HCM.FHM.AKAT | U37: C99.I5.SANS 2026 | V37: C99.I5.WM.AA 2026 | W37: =IF(U37="","",IFERROR(_xlfn.XLOOKUP(U37,Mapping!$A:$A,Mapping!$B:$B),"")) -> Project_023 | X37: =IF(V37="","",IFERROR(_xlfn.XLOOKUP(V37,Mapping!$A:$A,Mapping!$B:$B),"")) -> Project_016 | Y37: External | Z37: NodeJs Server Implementation
A38: 37 | B38: Nguyễn Công Đắc | C38: user037 | D38: OFF | E38: 44348 | F38: Senior Software Engineer | G38: 755 | H38: GitHub Copilot;EnglishScore;Cloud Developer;AWS Cloud Architect;PROFESSIONAL SCRUM MASTER™ I | I38: FHM CMS | J38: HCM | K38: FHM | L38: FHM CMS | M38: CAD Engineering | O38: IT Service | P38: Expert | Q38: DEVE04 | R38: COX-AM | S38: =VLOOKUP(R38,Customer_Mapping!A:B,2,FALSE) -> Customer_009 | T38: FSO.HCM.FHM.AKAT | U38: FMCS3 | V38: C99.I5.SANS 2026 | W38: =IF(U38="","",IFERROR(_xlfn.XLOOKUP(U38,Mapping!$A:$A,Mapping!$B:$B),"")) -> Project_017 | X38: =IF(V38="","",IFERROR(_xlfn.XLOOKUP(V38,Mapping!$A:$A,Mapping!$B:$B),"")) -> Project_023 | Y38: External | Z38: CAD Engineering
A39: 38 | B39: Mai Thanh Đại | C39: user038 | D39: OFF | E39: 45192 | F39: Solution Architect | G39: 785 | H39: Google Cloud Certified Generative AI Leader;EnglishScore;AWS Certified Solutions Architect - Associate | I39: FHM CMS | J39: HCM | K39: FHM | L39: FHM CMS | M39: Java Framework | N39: Senior | O39: AWS Cloud | P39: Senior | Q39: SARE02 | R39: FR | S39: =VLOOKUP(R39,Customer_Mapping!A:B,2,FALSE) -> Customer_001 | T39: FSO.HCM.FHM.CMS | U39: FRDLO | V39: FMCS3 | W39: =IF(U39="","",IFERROR(_xlfn.XLOOKUP(U39,Mapping!$A:$A,Mapping!$B:$B),"")) -> Project_001 | X39: =IF(V39="","",IFERROR(_xlfn.XLOOKUP(V39,Mapping!$A:$A,Mapping!$B:$B),"")) -> Project_017 | Y39: Hien | Z39: Java Framework
A40: 39 | B40: Ngô Minh Đại | C40: user039 | D40: OFF | E40: 46135 | F40: Senior Auto Test Engineer | I40: FHM CMS | J40: HCM | K40: FHM | L40: FHM CMS | O40: Manual Test | P40: Senior | Q40: ATES04 | R40: FR | S40: =VLOOKUP(R40,Customer_Mapping!A:B,2,FALSE) -> Customer_001 | T40: FSO.HCM.FHM.CMS | U40: SBR_Buhin26 | V40: FRDLO | W40: =IF(U40="","",IFERROR(_xlfn.XLOOKUP(U40,Mapping!$A:$A,Mapping!$B:$B),"")) -> Project_005 | X40: =IF(V40="","",IFERROR(_xlfn.XLOOKUP(V40,Mapping!$A:$A,Mapping!$B:$B),"")) -> Project_001 | Y40: External
...

Sheet Update Agent usage sync
A1: no | B1: account | C1: v0.10.5 | D1: v0.10.8 | E1: v0.10.10 | F1: v0.10.12 | G1: v0.10.13 | H1: v0.0.15
A2: 1 | B2: user001 | C2: 1 | D2: 0 | E2: 0 | F2: 1 | G2: 0 | H2: =IF(RAND()<0.6,0,1) -> 1
A3: 2 | B3: user002 | C3: 1 | D3: 1 | E3: 0 | F3: 1 | G3: 1 | H3: =IF(RAND()<0.6,0,1) -> 1
A4: 3 | B4: user003 | C4: 0 | D4: 1 | E4: 0 | F4: 0 | G4: 1 | H4: =IF(RAND()<0.6,0,1) -> 1
A5: 4 | B5: user004 | C5: 1 | D5: 1 | E5: 1 | F5: 0 | G5: 0 | H5: =IF(RAND()<0.6,0,1) -> 0
A6: 5 | B6: user005 | C6: 1 | D6: 0 | E6: 1 | F6: 1 | G6: 1 | H6: =IF(RAND()<0.6,0,1) -> 0
A7: 6 | B7: user006 | C7: 1 | D7: 0 | E7: 1 | F7: 0 | G7: 0 | H7: =IF(RAND()<0.6,0,1) -> 1
A8: 7 | B8: user007 | C8: 0 | D8: 0 | E8: 0 | F8: 0 | G8: 1 | H8: =IF(RAND()<0.6,0,1) -> 0
A9: 8 | B9: user008 | C9: 1 | D9: 0 | E9: 0 | F9: 0 | G9: 0 | H9: =IF(RAND()<0.6,0,1) -> 0
A10: 9 | B10: user009 | C10: 0 | D10: 1 | E10: 0 | F10: 0 | G10: 1 | H10: =IF(RAND()<0.6,0,1) -> 1
A11: 10 | B11: user010 | C11: 1 | D11: 0 | E11: 0 | F11: 1 | G11: 1 | H11: =IF(RAND()<0.6,0,1) -> 0
A12: 11 | B12: user011 | C12: 0 | D12: 0 | E12: 1 | F12: 1 | G12: 0 | H12: =IF(RAND()<0.6,0,1) -> 0
A13: 12 | B13: user012 | C13: 0 | D13: 1 | E13: 0 | F13: 0 | G13: 0 | H13: =IF(RAND()<0.6,0,1) -> 0
... A390: 389 | B390: user389 | C390: 1 | D390: 0 | E390: 0 | F390: 1 | G390: 1 | H390: =IF(RAND()<0.6,0,1) -> 1

Sheet Worklog Compliance
D1: Total Worklog (h)
A2: employee_id | B2: Total | C2: unlogged_days | D2: 8/10 | E2: 8/11 | F2: 8/12 | G2: 8/13 | H2: 8/14 | I2: 8/17 | J2: 8/18 | K2: 8/19 | L2: 8/20 | M2: 8/21 | N2: 8/24 | O2: 8/25 | P2: 8/26 | Q2: 8/27 | R2: 8/28 | S2: 9/3 | T2: 9/4
A3: 1 | B3: =COUNTIF(D3:T3,0) -> 16 | C3: {=_xlfn.TEXTJOIN(", ",TRUE,IF(D3:T3=0,TEXT(D$2:T$2,"dd/mm"),""))} -> 10/08, 11/08, 12/08, 13/08, 14/08, 18/08, 19/08, 20/08, 21/08, 24/08, 25/08, 26/08, 27/08, 28/08, 03/09, 04/09 | D3: 0 | E3: 0 | F3: 0 | G3: 0 | H3: 0 | I3: 12 | J3: 0 | K3: 0 | L3: 0 | M3: 0 | N3: 0 | O3: 0 | P3: 0 | Q3: 0 | R3: 0 | S3: 0 | T3: 0
A4: 2 | B4: =COUNTIF(D4:T4,0) -> 15 | C4: {=_xlfn.TEXTJOIN(", ",TRUE,IF(D4:T4=0,TEXT(D$2:T$2,"dd/mm"),""))} -> 10/08, 11/08, 12/08, 13/08, 17/08, 18/08, 19/08, 20/08, 21/08, 24/08, 25/08, 26/08, 27/08, 03/09, 04/09 | D4: 0 | E4: 0 | F4: 0 | G4: 0 | H4: 8 | I4: 0 | J4: 0 | K4: 0 | L4: 0 | M4: 0 | N4: 0 | O4: 0 | P4: 0 | Q4: 0 | R4: 8 | S4: 0 | T4: 0
A5: 3 | B5: =COUNTIF(D5:T5,0) -> 16 | C5: {=_xlfn.TEXTJOIN(", ",TRUE,IF(D5:T5=0,TEXT(D$2:T$2,"dd/mm"),""))} -> 10/08, 11/08, 12/08, 13/08, 14/08, 17/08, 18/08, 19/08, 20/08, 21/08, 24/08, 25/08, 27/08, 28/08, 03/09, 04/09 | D5: 0 | E5: 0 | F5: 0 | G5: 0 | H5: 0 | I5: 0 | J5: 0 | K5: 0 | L5: 0 | M5: 0 | N5: 0 | O5: 0 | P5: 8 | Q5: 0 | R5: 0 | S5: 0 | T5: 0
A6: 4 | B6: =COUNTIF(D6:T6,0) -> 3 | C6: {=_xlfn.TEXTJOIN(", ",TRUE,IF(D6:T6=0,TEXT(D$2:T$2,"dd/mm"),""))} -> 17/08, 18/08, 03/09 | D6: 8 | E6: 8 | F6: 8 | G6: 8 | H6: 8 | I6: 0 | J6: 0 | K6: 8 | L6: 8 | M6: 8 | N6: 8 | O6: 8 | P6: 8 | Q6: 8 | R6: 8 | S6: 0 | T6: 4
A7: 5 | B7: =COUNTIF(D7:T7,0) -> 16 | C7: {=_xlfn.TEXTJOIN(", ",TRUE,IF(D7:T7=0,TEXT(D$2:T$2,"dd/mm"),""))} -> 10/08, 11/08, 12/08, 13/08, 14/08, 17/08, 18/08, 20/08, 21/08, 24/08, 25/08, 26/08, 27/08, 28/08, 03/09, 04/09 | D7: 0 | E7: 0 | F7: 0 | G7: 0 | H7: 0 | I7: 0 | J7: 0 | K7: 8 | L7: 0 | M7: 0 | N7: 0 | O7: 0 | P7: 0 | Q7: 0 | R7: 0 | S7: 0 | T7: 0
A8: 6 | B8: =COUNTIF(D8:T8,0) -> 17 | C8: {=_xlfn.TEXTJOIN(", ",TRUE,IF(D8:T8=0,TEXT(D$2:T$2,"dd/mm"),""))} -> 10/08, 11/08, 12/08, 13/08, 14/08, 17/08, 18/08, 19/08, 20/08, 21/08, 24/08, 25/08, 26/08, 27/08, 28/08, 03/09, 04/09 | D8: 0 | E8: 0 | F8: 0 | G8: 0 | H8: 0 | I8: 0 | J8: 0 | K8: 0 | L8: 0 | M8: 0 | N8: 0 | O8: 0 | P8: 0 | Q8: 0 | R8: 0 | S8: 0 | T8: 0
A9: 7 | B9: =COUNTIF(D9:T9,0) -> 17 | C9: {=_xlfn.TEXTJOIN(", ",TRUE,IF(D9:T9=0,TEXT(D$2:T$2,"dd/mm"),""))} -> 10/08, 11/08, 12/08, 13/08, 14/08, 17/08, 18/08, 19/08, 20/08, 21/08, 24/08, 25/08, 26/08, 27/08, 28/08, 03/09, 04/09 | D9: 0 | E9: 0 | F9: 0 | G9: 0 | H9: 0 | I9: 0 | J9: 0 | K9: 0 | L9: 0 | M9: 0 | N9: 0 | O9: 0 | P9: 0 | Q9: 0 | R9: 0 | S9: 0 | T9: 0
A10: 8 | B10: =COUNTIF(D10:T10,0) -> 17 | C10: {=_xlfn.TEXTJOIN(", ",TRUE,IF(D10:T10=0,TEXT(D$2:T$2,"dd/mm"),""))} -> 10/08, 11/08, 12/08, 13/08, 14/08, 17/08, 18/08, 19/08, 20/08, 21/08, 24/08, 25/08, 26/08, 27/08, 28/08, 03/09, 04/09 | D10: 0 | E10: 0 | F10: 0 | G10: 0 | H10: 0 | I10: 0 | J10: 0 | K10: 0 | L10: 0 | M10: 0 | N10: 0 | O10: 0 | P10: 0 | Q10: 0 | R10: 0 | S10: 0 | T10: 0
A11: 9 | B11: =COUNTIF(D11:T11,0) -> 9 | C11: {=_xlfn.TEXTJOIN(", ",TRUE,IF(D11:T11=0,TEXT(D$2:T$2,"dd/mm"),""))} -> 11/08, 13/08, 17/08, 19/08, 24/08, 27/08, 28/08, 03/09, 04/09 | D11: 8 | E11: 0 | F11: 8 | G11: 0 | H11: 8 | I11: 0 | J11: 8 | K11: 0 | L11: 4.3 | M11: 1 | N11: 0 | O11: 8 | P11: 8 | Q11: 0 | R11: 0 | S11: 0 | T11: 0
A12: 10 | B12: =COUNTIF(D12:T12,0) -> 13 | C12: {=_xlfn.TEXTJOIN(", ",TRUE,IF(D12:T12=0,TEXT(D$2:T$2,"dd/mm"),""))} -> 10/08, 11/08, 12/08, 13/08, 14/08, 17/08, 19/08, 20/08, 21/08, 25/08, 26/08, 27/08, 04/09 | D12: 0 | E12: 0 | F12: 0 | G12: 0 | H12: 0 | I12: 0 | J12: 8 | K12: 0 | L12: 0 | M12: 0 | N12: 8 | O12: 0 | P12: 0 | Q12: 0 | R12: 8 | S12: 8 | T12: 0
A13: 11 | B13: =COUNTIF(D13:T13,0) -> 3 | C13: {=_xlfn.TEXTJOIN(", ",TRUE,IF(D13:T13=0,TEXT(D$2:T$2,"dd/mm"),""))} -> 20/08, 28/08, 03/09 | D13: 8 | E13: 8 | F13: 8 | G13: 8 | H13: 8 | I13: 8 | J13: 8 | K13: 6 | L13: 0 | M13: 8 | N13: 8 | O13: 8 | P13: 8 | Q13: 8 | R13: 0 | S13: 0 | T13: 8
A14: 12 | B14: =COUNTIF(D14:T14,0) -> 6 | C14: {=_xlfn.TEXTJOIN(", ",TRUE,IF(D14:T14=0,TEXT(D$2:T$2,"dd/mm"),""))} -> 11/08, 14/08, 26/08, 28/08, 03/09, 04/09 | D14: 8 | E14: 0 | F14: 8 | G14: 8 | H14: 0 | I14: 8 | J14: 8 | K14: 8 | L14: 8 | M14: 8 | N14: 8 | O14: 8 | P14: 0 | Q14: 8 | R14: 0 | S14: 0 | T14: 0
... A35: 33 | B35: =COUNTIF(D35:T35,0) -> 17 | C35: {=_xlfn.TEXTJOIN(", ",TRUE,IF(D35:T35=0,TEXT(D$2:T$2,"dd/mm"),""))} -> 10/08, 11/08, 12/08, 13/08, 14/08, 17/08, 18/08, 19/08, 20/08, 21/08, 24/08, 25/08, 26/08, 27/08, 28/08, 03/09, 04/09 | D35: 0 | E35: 0 | F35: 0 | G35: 0 | H35: 0 | I35: 0 | J35: 0 | K35: 0 | L35: 0 | M35: 0 | N35: 0 | O35: 0 | P35: 0 | Q35: 0 | R35: 0 | S35: 0 | T35: 0

Sheet Certificate registration
A1: employee_id | B1: AI Certification | C1: AI Claude
A2: 1 | B2: 0 | C2: 0
A3: 2 | B3: 1 | C3: 1
A4: 3 | B4: 1 | C4: 0
A5: 4 | B5: 0 | C5: 0
A6: 5 | B6: 0 | C6: 0
A7: 6 | B7: 0 | C7: 0
A8: 7 | B8: 0 | C8: 1
A9: 8 | B9: 0 | C9: 1
A10: 9 | B10: 0 | C10: 1
A11: 10 | B11: 0 | C11: 0
A12: 11 | B12: 0 | C12: 0
A13: 12 | B13: 1 | C13: 1
... A39: 38 | B39: 1 | C39: 1
A40: 39
A41: 40
A42: 41
A43: 42
A44: 43
A45: 44
A46: 45
A47: 46
A48: 47
A49: 48
A50: 49

Sheet KG data training
A1: STT | B1: training_hours | C1: manager_support_score | D1: burnout_score | E1: engagement_score | F1: work_life_balance_score | G1: performance_rating | H1: last_review_score | I1: uses_ai_tools_at_work | J1: perceived_ai_job_risk
A2: 1 | B2: 17 | C2: 9.4 | D2: 1 | E2: 9.7 | F2: 7.7 | G2: 3 | H2: 8.3 | I2: TRUE | J2: 4.8
A3: 2 | B3: 21 | C3: 4.2 | D3: 1.9 | E3: 5.4 | F3: 7.8 | G3: 3 | H3: 8 | I3: TRUE | J3: 2.9
A4: 3 | B4: 22 | C4: 7.5 | D4: 5.3 | E4: 6.5 | F4: 7 | G4: 4 | H4: 9.5 | I4: TRUE | J4: 7.2
A5: 4 | B5: 21 | C5: 8.7 | D5: 4.3 | E5: 7.3 | F5: 3.5 | G5: 4 | H5: 7.9 | I5: FALSE | J5: 5.2
A6: 5 | B6: 20 | C6: 7.5 | D6: 2.3 | E6: 7 | F6: 7.2 | G6: 4 | H6: 8.5 | I6: FALSE | J6: 6.4
A7: 6 | B7: 13 | C7: 6.8 | D7: 4.5 | E7: 8.2 | F7: 7 | G7: 4 | H7: 7.9 | I7: TRUE | J7: 7.3
A8: 7 | B8: 7 | C8: 10 | D8: 3.8 | E8: 6.2 | F8: 6.9 | G8: 4 | H8: 7.5 | I8: FALSE | J8: 7.9
A9: 8 | B9: 16 | C9: 5.4 | D9: 5.5 | E9: 7.2 | F9: 7 | G9: 4 | H9: 10 | I9: TRUE | J9: 3.7
A10: 9 | B10: 17 | C10: 7.3 | D10: 5.1 | E10: 7.5 | F10: 5.7 | G10: 3 | H10: 9.5 | I10: TRUE | J10: 4.8
A11: 10 | B11: 41 | C11: 8.6 | D11: 2.3 | E11: 9.1 | F11: 6.3 | G11: 4 | H11: 8.8 | I11: FALSE | J11: 5.5
A12: 11 | B12: 27 | C12: 3.1 | D12: 3.8 | E12: 4.7 | F12: 7.3 | G12: 3 | H12: 5.8 | I12: FALSE | J12: 5.6
A13: 12 | B13: 21 | C13: 4.4 | D13: 6.3 | E13: 5.1 | F13: 4.7 | G13: 4 | H13: 10 | I13: TRUE | J13: 8.5
... A49: 48 | B49: 14 | C49: 7 | D49: 2.7 | E49: 6.1 | F49: 6.3 | G49: 4 | H49: 10 | I49: TRUE | J49: 4

Sheet Bảng data nhân sự full
A1: STT | B1: Full Name | C1: Account | D1: Contract Type | E1: Hire Date | F1: Job Title | G1: Toeic Score | H1: Certificates | I1: Department | J1: Location | K1: Parent Department | L1: Child Department | M1: Main Skill | N1: Seniority(Main) | O1: Current Skill | P1: Seniority(Current)
A2: 1 | B2: Lê Văn Thân | C2: ThanLV | D2: OFF | E2: 44958 | F2: Senior Project Manager | G2: 955 | H2: EnglishScore;Project Management Professional (PMP) | I2: FHM CMS | J2: HCM | K2: FHM | L2: FHM CMS | M2: Project Management | O2: Project Management | P2: Middle
A3: 2 | B3: Nguyễn Đông Hiếu | C3: HieuND97 | D3: OFF | E3: 46082 | F3: Project Manager | I3: FHM CMS | J3: HCM | K3: FHM | L3: FHM CMS | O3: Project Management | P3: Middle
A4: 3 | B4: Nguyễn Minh Nhựt | C4: NhutNM5 | D4: OFF | E4: 44667 | F4: Associate Project Manager | G4: 910 | H4: PROFESSIONAL SCRUM MASTER™ I;EnglishScore;PROFESSIONAL SCRUM MASTER™ II;Oracle Cloud Infrastructure 2023 Certified Foundations Associate;Oracle Cloud Data Management 2023 Certified Foundations Associate;Oracle Cloud Infrastructure 2023 AI Certified Foundations Associate;Core Designer Certificate;Advanced Designer Certificate;Oracle Cloud Infrastructure for Sunbird Ed Specialty;Aptis General - Listening Reading Speaking Writing - Level B2 | I4: FHM CMS | J4: HCM | K4: FHM | L4: FHM CMS | M4: .NET Framework | N4: Junior | O4: Project Management | P4: Junior
A5: 4 | B5: Nguyễn Hoàng Tuyên | C5: TuyenNH1 | D5: OFF | E5: 43062 | F5: Project Manager | G5: 620 | H5: C++ Standard Template Library;EnglishScore;FSOFT Foreign Language Proficiency Test - TOEIC Test;PROFESSIONAL SCRUM MASTER™ I;TOEIC (Internal);PMI Agile Certified Practitioner (PMI-ACP)® | I5: FHM CMS | J5: HCM | K5: FHM | L5: FHM CMS | M5: Project Management | O5: Project Management | P5: Junior
A6: 5 | B6: Tran Duc Hien | C6: HienDT25 | D6: OFF | E6: 45427 | F6: Senior Software Engineer | G6: 720 | H6: EnglishScore;Azure Fundamentals | I6: FHM CMS | J6: HCM | K6: FHM | L6: FHM CMS | M6: .NET Framework | O6: .NET Framework | P6: Middle
A7: 6 | B7: Nguyen Hoang Thong | C7: ThongNH7 | D7: OFF | E7: 45870 | F7: Solution Architect | G7: 740 | H7: Google Cloud Certified Professional Cloud Developer;Google Cloud Certified - Associate Cloud Engineer;Microsoft Certified: Azure Fundamentals;Microsoft Certified: Azure Developer Associate;Microsoft Certified: Azure Data Engineer Associate;Microsoft Certified: Azure Solutions Architect Expert;Microsoft Certified: DevOps Engineer Expert;Cloud Architect using Microsoft Azure;EnglishScore;FSOFT Foreign Language Proficiency Test - TOEIC Test;GitHub Copilot;Agile Scrum Foundation;Secure Coding | I7: FHM CMS | J7: HCM | K7: FHM | L7: FHM CMS | M7: .NET Framework | O7: Azure Cloud | P7: Middle
A8: 7 | B8: Châu Hồng Vũ | C8: VuCH2 | D8: OFF | E8: 43983 | F8: Solution Architect | G8: 755 | H8: Google Cloud Certified Professional Cloud Developer;Core Designer Certificate;Advanced Designer Certificate;Microsoft Certified: Azure Data Engineer Associate;Microsoft Certified: Azure Database Administrator Associate;Microsoft Certified: Azure IoT Developer Specialty;Microsoft Certified: Azure Solutions Architect Expert;Microsoft Certified: DevOps Engineer Expert;Google Cloud Certified - Associate Cloud Engineer;Microsoft Certified: Azure Fundamentals;Microsoft Certified: Azure Developer Associate;FSOFT Foreign Language Proficiency Test - TOEIC Test;EnglishScore;Cloud Architect using Microsoft Azure | I8: FHM CMS | J8: HCM | K8: FHM | L8: FHM CMS | M8: .NET Framework | N8: Middle | O8: Azure Cloud | P8: Senior
